Workbook
Name A: #REF!
Name A: #REF!

Sheet Tong hop
B1: BẢNG TỔNG HỢP SỐ LƯỢNG SÔNG, KÊNH, RẠCH TRÊN ĐỊA BÀN THÀNH PHỐ
B2: (Kèm theo Quyết định số 28/2016/QĐ-UBND ngày 12 tháng 8 năm 2016 của Ủy ban nhân dân Thành phố
A4: TT | B4: Đơn vị trực tiếp quản lý | C4: Tổng số lượng sông, kênh, rạch | D4: Tổng chiều dài (m) | E4: Ghi chú
A5: I | B5: Phụ lục 1: Danh mục các tuyến sông, kênh, rạch có chức năng tiêu thoát nước trên địa bàn Thành phố | C5: =C6+C7+C8 -> 849 | D5: =SUM(D6:D8) -> 1095130.7
A6: 1 | B6: Giao Trung tâm Điều hành Chương trình chống ngập nước Thành phố | C6: ='Thoat nuoc'!A727 -> 701 | D6: ='Thoat nuoc'!B727 -> 798253.74
A7: 2 | B7: Giao Ủy ban nhân dân quận Bình Tân | C7: ='Thoat nuoc'!A751 -> 24 | D7: ='Thoat nuoc'!B728 -> 22424
A8: 3 | B8: Giao Ủy ban nhân dân huyện Cần Giờ | C8: ='Thoat nuoc'!A875 -> 124 | D8: ='Thoat nuoc'!B729 -> 274453
A9: II | B9: Phụ lục 2: Danh mục các tuyến sông, kênh, rạch có chức năng giao thông thủy trên địa bàn Thành phố | C9: 112 | D9: 975500
A10: III | B10: Phụ lục 3: Danh mục các tuyến kênh, rạch có chức năng tưới tiêu phục vụ sản xuất nông nghiệp, nuôi trồng thủy sản, phát triển rừng và sản xuất muối trên địa bàn Thành phố | C10: =C11+C12 -> 1992 | D10: =D11+D12 -> 2300403
A11: 1 | B11: Giao Công ty TNHH MTV Quản lý khai thác dịch vụ Thủy lợi Thành phố | C11: ='Tuoi tieu nong nghiep'!A9 -> 1226 | D11: ='Tuoi tieu nong nghiep'!B9 -> 1234244
A12: 2 | B12: Ủy ban nhân dân các quận - huyện, trong đó: | C12: =SUM(C13:C19) -> 766 | D12: =SUM(D13:D19) -> 1066159
A13: a | B13: Giao Ủy ban nhân dân quận 9 | C13: ='Tuoi tieu nong nghiep'!A1241 -> 8 | D13: ='Tuoi tieu nong nghiep'!B1241 -> 6236
A14: b | B14: Giao Ủy ban nhân dân 12 | C14: ='Tuoi tieu nong nghiep'!A1291 -> 50 | D14: ='Tuoi tieu nong nghiep'!B1291 -> 24304.7
A15: c | B15: Giao Ủy ban nhân dân huyện Hóc Môn | C15: ='Tuoi tieu nong nghiep'!A1399 -> 108 | D15: ='Tuoi tieu nong nghiep'!B1399 -> 78219
A16: d | B16: Giao Ủy ban nhân dân huyện Bình Chánh | C16: ='Tuoi tieu nong nghiep'!A1498 -> 99 | D16: ='Tuoi tieu nong nghiep'!B1498 -> 163245
A17: đ | B17: Giao Ủy ban nhân dân huyện Củ Chi | C17: ='Tuoi tieu nong nghiep'!A1824 -> 326 | D17: ='Tuoi tieu nong nghiep'!B1824 -> 352530.3
A18: e | B18: Giao Ủy ban nhân dân huyện Nhà Bè | C18: ='Tuoi tieu nong nghiep'!A1858 -> 34 | D18: ='Tuoi tieu nong nghiep'!B1858 -> 82000
A19: g | B19: Giao Ủy ban nhân dân huyện Cần Giờ | C19: ='Tuoi tieu nong nghiep'!A1999 -> 141 | D19: ='Tuoi tieu nong nghiep'!B1999 -> 359624
A20: IV | B20: Tổng cộng I+II+II | C20: =C5+C9+C10 -> 2953 | D20: =D5+D9+D10 -> 4371033.7
B22: ỦY BAN NHÂN DÂN THÀNH PHỐ

Sheet Thoat nuoc
C1: Phụ lục 1: Danh mục các tuyến sông, kênh, rạch có chức năng tiêu thoát nước trên địa bàn Thành phố (Kèm theo Quyết định số 28/2016/QĐ-UBND ngày 12 tháng 8 năm 2016 của Ủy ban nhân dân Thành phố)
C4: STT | D4: Tên sông, kênh, rạch | E4: Địa điểm (quận - huyện) | F4: Quản lý ngành | G4: Quản lý trực tiếp | H4: Lý trình | J4: Hiện trạng
H5: Điểm đầu | I5: Điểm cuối | J5: Dài (m) | K5: Rộng (m) | L5: Ghi chú
C6: Tổng cộng 849 tuyến, tổng chiều dài 1.094.105m | J6: =SUM(J7:J875) -> 1095130.7
C7: 1 | D7: Rạch Cầu Dừa | E7: 4 | F7: Sở Giao thông vận tải | G7: Trung tâm ĐHCT chống ngập nước TP | H7: Hẻm 209 Tôn Thất Thuyết | I7: Cầu Dừa quận 4 (Kênh Bến Nghé) | J7: 640 | K7: 6.1
C8: 2 | D8: Rạch Cầu Dừa nhánh 1 | E8: 4 | F8: Sở Giao thông vận tải | G8: Trung tâm ĐHCT chống ngập nước TP | H8: Khu dân cư cuối đường Hoàng Diệu | I8: Rạch Cầu Dừa | J8: 110 | K8: 1.4
C9: 3 | D9: Rạch Cầu Dừa nhánh 2 | E9: 4 | F9: Sở Giao thông vận tải | G9: Trung tâm ĐHCT chống ngập nước TP | H9: Khu dân cư đường Khánh Hội | I9: Rạch Cầu Dừa | J9: 410 | K9: 2.2
C10: 4 | D10: Kênh Tân Hoá đoạn 1 | E10: 11+Tân Phú | F10: Sở Giao thông vận tải | G10: Trung tâm ĐHCT chống ngập nước TP | H10: Bùi Cẩm Hổ | I10: Ngã 3 kênh Tân Hóa - Bàu Trâu | J10: 900 | K10: 20
D11: Kênh Tân Hoá đoạn 2 | E11: 6 | F11: Sở Giao thông vận tải | G11: Trung tâm ĐHCT chống ngập nước TP | H11: Ngã 3 kênh Tân Hóa - Bàu Trâu | I11: Cầu Ông Buông 2 | J11: 698 | K11: 10.9
C12: 5 | D12: Rạch Hàng Bàng đoạn 1 | E12: 5 | F12: Sở Giao thông vận tải | G12: Trung tâm ĐHCT chống ngập nước TP | H12: Kênh Tàu Hủ | I12: Góc Bến Bãi Sậy-đường Vạn Tượng | J12: 120 | K12: 7
D13: Rạch Hàng Bàng đoạn 2 | E13: 5+6 | F13: Sở Giao thông vận tải | G13: Trung tâm ĐHCT chống ngập nước TP | H13: Góc Bến Bãi Sậy-đường Vạn Tượng | I13: Phạm Đình Hổ | J13: 726 | K13: 2
D14: Rạch Hàng Bàng đoạn 3 | E14: 6 | F14: Sở Giao thông vận tải | G14: Trung tâm ĐHCT chống ngập nước TP | H14: Minh Phụng | I14: Kênh Tân Hóa- Lò Gốm | J14: 267 | K14: 2.9
C15: 6 | D15: Rạch Bàu Trâu | E15: 6+Tân Phú | F15: Sở Giao thông vận tải | G15: Trung tâm ĐHCT chống ngập nước TP | H15: Cuối kênh Hiệp Tân | I15: Kênh Tân Hóa | J15: 1577 | K15: 7
C16: 7 | D16: Rạch Ruột Ngựa đoạn 1 | E16: 8 | F16: Sở Giao thông vận tải | G16: Trung tâm ĐHCT chống ngập nước TP | H16: Cuối tuyến (giao rạch Nhỏ) | I16: Giao rạch Ruột Ngựa - rạch Nhảy | J16: 1428 | K16: 20.6
D17: Rạch Ruột Ngựa đoạn 2 | E17: 8 | F17: Sở Giao thông vận tải | G17: Trung tâm ĐHCT chống ngập nước TP | H17: Giao rạch Ruột Ngựa - rạch Nhảy | I17: Cầu Phú Định | J17: 814 | K17: 42.8
C18: 8 | D18: Rạch Ruột Ngựa (nhánh 1) | E18: 8 | F18: Sở Giao thông vận tải | G18: Trung tâm ĐHCT chống ngập nước TP | H18: Khu dân cư đường An Dương Vương | I18: Rạch Ruột Ngựa | J18: 291 | K18: 7
C19: 9 | D19: Rạch Nhảy | E19: 8 | F19: Sở Giao thông vận tải | G19: Trung tâm ĐHCT chống ngập nước TP | H19: Cầu Mỹ Thuận | I19: Giao rạch Ruột Ngựa - rạch Nhảy | J19: 1540 | K19: 21.7
C20: 10 | D20: Rạch Bà Cả | E20: 8 | F20: Sở Giao thông vận tải | G20: Trung tâm ĐHCT chống ngập nước TP | H20: Đường 42 (Thanh Niên) | I20: Rạch Ruột Ngựa | J20: 421 | K20: 7.8
C21: 11 | D21: Rạch Nhỏ (Bà Lựu nối dài) | E21: 8 | F21: Sở Giao thông vận tải | G21: Trung tâm ĐHCT chống ngập nước TP | H21: Đường An Dương Vương | I21: Giao Rạch Ruột Ngựa | J21: 730 | K21: 7.1
C22: 12 | D22: Kênh Ngang số 1 | E22: 8 | F22: Sở Giao thông vận tải | G22: Trung tâm ĐHCT chống ngập nước TP | H22: Kênh Đôi | I22: Kênh Tàu Hủ | J22: 400
C23: 13 | D23: Kênh Ụ Cây | E23: 8 | F23: Sở Giao thông vận tải | G23: Trung tâm ĐHCT chống ngập nước TP | H23: Kênh Đôi | I23: Kênh Tàu Hủ | J23: 775 | K23: 11.6
C24: 14 | D24: Rạch Ông Lớn nhánh 5 | E24: 8 | F24: Sở Giao thông vận tải | G24: Trung tâm ĐHCT chống ngập nước TP | H24: Khu dân cư đường Tạ Quang Bửu | I24: Ông Lớn nhánh 1 | J24: 231 | K24: 4.1
C25: 15 | D25: Rạch Ông Nhỏ | E25: 8 | F25: Sở Giao thông vận tải | G25: Trung tâm ĐHCT chống ngập nước TP | H25: Rạch Du | I25: Rạch Ông Lớn | J25: 1960 | K25: 20
C26: 16 | D26: Rạch Ông Nhỏ nhánh 1 | E26: 8 | F26: Sở Giao thông vận tải | G26: Trung tâm ĐHCT chống ngập nước TP | H26: Thượng nguồn khu dân cư | I26: Rạch Ông Nhỏ | J26: 291 | K26: 5
C27: 17 | D27: Rạch Ông Nhỏ nhánh 2 | E27: 8 | F27: Sở Giao thông vận tải | G27: Trung tâm ĐHCT chống ngập nước TP | H27: Thượng nguồn khu dân cư | I27: Rạch Ông Nhỏ | J27: 236 | K27: 4.8
C28: 18 | D28: Rạch Ông Nhỏ nhánh 3 | E28: 8 | F28: Sở Giao thông vận tải | G28: Trung tâm ĐHCT chống ngập nước TP | H28: Ranh Bình Chánh - Quận 8 | I28: Rạch Ông Nhỏ | J28: 320 | K28: 6.5
C29: 19 | D29: Rạch Ông Nhỏ nhánh 4 | E29: 8 | F29: Sở Giao thông vận tải | G29: Trung tâm ĐHCT chống ngập nước TP | H29: Thượng nguồn khu dân cư | I29: Rạch Ông Nhỏ | J29: 292 | K29: 5.8
C30: 20 | D30: Rạch Ông Nhỏ nhánh 5 | E30: 8 | F30: Sở Giao thông vận tải | G30: Trung tâm ĐHCT chống ngập nước TP | H30: Thượng nguồn khu dân cư (đường mới) | I30: Rạch Ông Nhỏ | J30: 163 | K30: 8.3
C31: 21 | D31: Rạch Ông Nhỏ nhánh 6 | E31: 8 | F31: Sở Giao thông vận tải | G31: Trung tâm ĐHCT chống ngập nước TP | H31: Thượng nguồn khu dân cư(đường mới) | I31: Rạch Ông Nhỏ | J31: 438 | K31: 6.2
C32: 22 | D32: Rạch Du | E32: 8 | F32: Sở Giao thông vận tải | G32: Trung tâm ĐHCT chống ngập nước TP | H32: Kênh Đôi | I32: Khu dân cư Xí nghiệp may Quận 8 | J32: 1240 | K32: 11
C33: 23 | D33: Rạch Hố Đen | E33: 8 | F33: Sở Giao thông vận tải | G33: Trung tâm ĐHCT chống ngập nước TP | H33: Rạch Ông Nhỏ nhánh 3 | I33: Đường Cao Lỗ | J33: 858 | K33: 2
C34: 24 | D34: Rạch Cầu Đồn đoạn 1 | E34: 8 | F34: Sở Giao thông vận tải | G34: Trung tâm ĐHCT chống ngập nước TP | H34: Bến Đò Đình | I34: Đường Tạ Quang Bửu | J34: 443 | K34: 4.5
D35: Rạch Cầu Đồn đoạn 2 | E35: 8 | F35: Sở Giao thông vận tải | G35: Trung tâm ĐHCT chống ngập nước TP | H35: Đường 42 | I35: Rạch Ruột Ngựa | J35: 645 | K35: 6.7
C36: 25 | D36: Nhánh Rạch Bà Tàng 1 | E36: 8 | F36: Sở Giao thông vận tải | G36: Trung tâm ĐHCT chống ngập nước TP | H36: Rạch Bà Tàng | I36: Cuối tuyến (Nguyễn Văn Linh) | J36: 1256 | K36: 8
C37: 26 | D37: Nhánh Rạch Bà Tàng 2 | E37: 8 | F37: Sở Giao thông vận tải | G37: Trung tâm ĐHCT chống ngập nước TP | H37: Rạch Bà Tàng | I37: Cuối tuyến | J37: 2356 | K37: 38.3
C38: 27 | D38: Nhánh Rạch Bà Tàng 3 | E38: 8 | F38: Sở Giao thông vận tải | G38: Trung tâm ĐHCT chống ngập nước TP | H38: Rạch Bà Tàng | I38: Cuối tuyến | J38: 1650 | K38: 16.1
C39: 28 | D39: Nhánh Rạch Bà Tàng 4 | E39: 8 | F39: Sở Giao thông vận tải | G39: Trung tâm ĐHCT chống ngập nước TP | H39: Rạch Bà Tàng | I39: Cuối tuyến | J39: 400 | K39: 20
C40: 29 | D40: Rạch Đầm Sen | E40: 11 | F40: Sở Giao thông vận tải | G40: Trung tâm ĐHCT chống ngập nước TP | H40: Chùa Giác Viên | I40: Ngã 3 kênh Tân Hóa - rạch Đầm Sen | J40: 713 | K40: 5.9
C41: 30 | D41: Rạch Bà Lựu (rạch Năng) | E41: Bình Tân | F41: Sở Giao thông vận tải | G41: Trung tâm ĐHCT chống ngập nước TP | H41: Hồ Học Lãm | I41: đường An Dương Vương | J41: 430 | K41: 3-8
C42: 31 | D42: Rạch Nhảy nhánh 1 | E42: Bình Tân | F42: Sở Giao thông vận tải | G42: Trung tâm ĐHCT chống ngập nước TP | H42: Đường Hồ Học Lãm | I42: Khu dân cư An Dương Vương | J42: 544 | K42: 2.1
...

Sheet PL1. So XD-Giao thong thuy
A1: PHỤ LỤC 1 DANH MỤC CÁC TUYẾN SÔNG, SUỐI, KÊNH, RẠCH CÓ CHỨC NĂNG GIAO THÔNG ĐƯỜNG THỦY NỘI ĐỊA THUỘC THẨM QUYỀN QUẢN LÝ CỦA ỦY BAN NHÂN DÂN THÀNH PHỐ HỒ CHÍ MINH PHÂN CẤP CHO SỞ XÂY DỰNG QUẢN LÝ, KHAI THÁC (Kèm theo Quyết định số 39/QĐ-UBND ngày 25 tháng 6 năm 2026 của Ủy ban nhân dân Thành phố Hồ Chí Minh)
A2: STT | B2: Tên Tuyến | C2: Phạm vi | E2: Chiều dài (km) | F2: Cấp kỹ thuật | H2: Ghi chú
C3: Điểm đầu (hạ lưu) | D3: Điểm cuối (thượng lưu) | F3: Quy hoạch | G3: Khai thác
A4: A. ĐƯỜNG THỦY NỘI ĐỊA QUỐC GIA PHÂN CẤP CHO UBND THÀNH PHỐ QUẢN LÝ
A5: 1 | B5: Sông Đồng Nai (bao gồm nhánh cù lao Rùa, cù lao Bạch Đằng) | C5: Cầu Đồng Nai | D5: Ngã ba Sông Bé | E5: 71.8 | H5: Thông tư số 09/2026/TT-BXD ngày 27 tháng 2 năm 2026 phân cấp quản lý nhà nước về giao thông đường thủy nội địa thuộc phạm vi quản lý của Bộ Xây dựng
A6: 2 | B6: Sông Sài Gòn | C6: Ngã ba rạch Bến Nghé | D6: Hạ lưu đập Dầu Tiếng 2 km | E6: 130.3
A7: 3 | B7: Kênh Tẻ - Kênh Đôi | C7: Ngã ba sông Sài Gòn | D7: Ngã ba sông Chợ Đệm Bến Lức | E7: 13
A8: 4 | B8: Sông Chợ Đệm - Bến Lức | C8: Ngã ba Kênh Đôi | D8: Cuối ranh giới xã Tân Nhựt – TP. Hồ Chí Minh | E8: 10.12
A9: 5 | B9: Rạch Ông Lớn - Kênh Cây Khô | C9: Ngã ba sông Cần Giuộc | D9: Ngã ba kênh Tẻ | E9: 8.5
A10: 6 | B10: Sông Cần Giuộc | C10: Đầu ranh giới xã Hưng Long – TP. Hồ Chí Minh | D10: Ngã ba kênh Cây Khô | E10: 5.81
A11: 7 | B11: Rạch Đào 1 | C11: Ngã ba sông Sài Gòn- Rạch Chiếc | D11: Đường nội bộ tổng kho Thủ Đức | E11: 1.1
A12: 8 | B12: Rạch Đào 2 | C12: Ngã ba sông Sài Gòn-Rạch Đào 2 | D12: Đường nội bộ tổng kho Thủ Đức | E12: 1.5
A13: B. ĐƯỜNG THỦY NỘI ĐỊA ĐỊA PHƯƠNG TRÊN ĐỊA BÀN THÀNH PHỐ
A14: I. | B14: KHU VỰC TRUNG TÂM
A15: 1 | B15: Rạch Láng The - Bến Mương | C15: Sông Sài Gòn | D15: Cầu Bến Mương | E15: 11.12 | F15: VI | G15: Chưa đạt cấp VI | H15: Quyết định số 1329/QĐ-UBND ngày 08 tháng 9 năm 2025 của Ủy ban nhân dân Thành phố Hồ Chí Minh công bố danh mục luồng đường thủy nội địa địa phương trên địa bàn Thành phố Hồ Chí Minh, giai đoạn năm 2025 đến năm 2027
A16: 2 | B16: Kênh Thầy Cai | C16: Kênh An Hạ | D16: Ranh giới Tây Ninh | E16: 25.4 | F16: V | G16: Chưa đạt cấp VI
A17: 3 | B17: Kênh Địa Phận | C17: Rạch Tra | D17: Rạch Láng The | E17: 10.84 | F17: VI | G17: Chưa đạt cấp VI
A18: 4 | B18: Rạch Tra | C18: Sông Sài Gòn | D18: Kênh Thầy Cai | E18: 11.15 | F18: IV | G18: VI
A19: 5 | B19: Kênh An Hạ | C19: Cầu Xáng TL10 | D19: Kênh Thầy Cai | E19: 15.16 | F19: V | G19: Chưa đạt cấp VI
A20: 6 | B20: Kênh Xáng An Hạ- kênh Xáng Lý Văn Mạnh | C20: Sông Bến Lức | D20: Cầu Xáng TL10 | E20: 18.45 | F20: IV | G20: VI
A21: 7 | B21: Rạch Cầu Mênh - Bến Cát | C21: Sông Trường Đay | D21: Rạch Tra | E21: 10.42 | F21: VI | G21: Chưa đạt cấp VI
A22: 8 | B22: Sông Vàm Thuật - Bến Cát - Trường Đay - Tham Lương - Rạch Nước Lên | C22: Sông Bến Lức | D22: Sông Sài Gòn | E22: 32.2 | F22: V | G22: -
A23: 9 | B23: Kênh Ngang Số 3 | C23: Kênh Đôi | D23: Kênh Tàu Hủ - Lò Gốm | E23: 0.46 | F23: V | G23: V
A24: 10 | B24: Kênh Ngang Số 2 | C24: Kênh Đôi | D24: Kênh Tàu Hủ - Lò Gốm | E24: 0.48 | F24: V | G24: V
A25: 11 | B25: Rạch Lò Gốm - Ông Buông | C25: Kênh Tàu Hủ - Lò Gốm | D25: Đường Bùi Cẩm Hổ | E25: 4.39 | F25: VI | G25: Chưa đạt cấp VI
A26: 12 | B26: Kênh Tàu Hủ - Lò Gốm | C26: Kênh Đôi | D26: Rạch Bến Nghé | E26: 8.89 | F26: V | G26: V
A27: 13 | B27: Rạch Bến Nghé | C27: Kênh Tàu Hủ | D27: Sông Sài Gòn | E27: 3.22 | F27: V | G27: Chưa đạt cấp VI
A28: 14 | B28: Rạch Nhiêu Lộc - Thị Nghè | C28: Sông Sài Gòn | D28: Cầu Lê Văn Sĩ | E28: 6 | F28: VI | G28: Chưa đạt cấp VI
C29: Cầu Lê Văn Sỹ | D29: đường Út Tịch | E29: 2.8 | F29: VI | G29: Chưa đạt cấp VI
A30: 15 | B30: Kênh Thanh Đa | C30: Sông Sài Gòn | D30: Sông Sài Gòn | E30: 1.6 | F30: V | G30: VI
A31: 16 | B31: Sông Vĩnh Bình | C31: Sông Sài Gòn | D31: Rạch Nước Trong | E31: 1.84 | F31: VI | G31: VI
A32: 17 | B32: Rạch Gò Dưa | C32: Sông Sài Gòn | D32: Cuối tuyến | E32: 4.52 | F32: VI | G32: Chưa đạt cấp VI
A33: 18 | B33: Rạch Chiếc - Trau Trảu | C33: Sông Sài Gòn | D33: Sông Tắc | E33: 11.1 | F33: IV | G33: Chưa đạt cấp VI
A34: 19 | B34: Rạch Ông Nhiêu | C34: Sông Đồng Nai | D34: Rạch Trau Trảu | E34: 7.42 | F34: IV | G34: VI | H34: Quyết định số 1329/QĐ-UBND ngày 08 tháng 9 năm 2025 của Ủy ban nhân dân Thành phố Hồ Chí Minh công bố danh mục luồng đường thủy nội địa địa phương trên địa bàn Thành phố Hồ Chí Minh, giai đoạn năm 2025 đến năm 2027
A35: 20 | B35: Rạch Cây Cam | C35: Sông Tắc | D35: Rạch Trau Trảu | E35: 3.32 | F35: VI | G35: Chưa đạt cấp VI
A36: 21 | B36: Rạch Môn - Sông Kinh | C36: Rạch Ông Nhiêu | D36: Sông Tắc | E36: 3.7 | F36: VI | G36: Chưa đạt cấp VI
A37: 22 | B37: Rạch Bà Đá - Rạch Giáng | C37: Sông Đồng Nai | D37: Sông Tắc | E37: 5.97 | F37: VI | G37: Chưa đạt cấp VI
A38: 23 | B38: Sông Tắc | C38: Sông Đồng Nai | D38: Sông Đồng Nai | E38: 11.99 | F38: IV | G38: VI
A39: 24 | B39: Rạch Bà Cua - Ông Cày | C39: Sông Đồng Nai | D39: Rạch Chiếc | E39: 7.4 | F39: VI | G39: Chưa đạt cấp VI
A40: 25 | B40: Rạch Đồng Trong - Rạch Giồng Ông Tố | C40: Sông Sài Gòn | D40: Rạch Chiếc | E40: 5.57 | F40: IV | G40: Chưa đạt cấp VI
...

Sheet PL2. So XD-Tieu thoat nuoc
A1: PHỤ LỤC 2 DANH MỤC CÁC TUYẾN SÔNG, SUỐI, KÊNH, RẠCH, HỒ, ĐẬP CÓ CHỨC NĂNG TIÊU THOÁT NƯỚC CHO KHU DÂN CƯ, KHU ĐÔ THỊ, KHU CÔNG NGHIỆP ĐI QUA ĐỊA GIỚI HÀNH CHÍNH TỪ 02 PHƯỜNG, XÃ TRỞ LÊN, CÁC TUYẾN TRỤC CHÍNH THUỘC THẨM QUYỀN QUẢN LÝ CỦA ỦY BAN NHÂN DÂN THÀNH PHỐ HỒ CHÍ MINH PHÂN CẤP CHO SỞ XÂY DỰNG QUẢN LÝ, KHAI THÁC (Kèm theo Quyết định số 39/QĐ-UBND ngày 25 tháng 6 năm 2026 của Ủy ban nhân dân Thành phố Hồ Chí Minh)
A2: STT | B2: Tên sông, kênh, rạch | C2: Địa điểm (phường, xã) | D2: Lý trình | F2: Quy mô
D3: Điểm đầu | E3: Điểm cuối | F3: Dài (m) | G3: Rộng (m) | H3: Ghi chú
A4: Tổng cộng 153 Tuyến | F4: =+F5+F138+F148 -> 241496.89
A5: A | B5: KHU VỰC TRUNG TÂM (132 Tuyến) | F5: =SUM(F6:F136) -> 157128.1
A6: 1 | B6: Rạch Hàng Bàng đoạn 1 | C6: Chợ Quán | D6: Kênh Tàu Hủ | E6: Góc Bến Bãi Sậy-đường Vạn Tượng | F6: 120 | G6: 7
A7: 2 | B7: Rạch Hàng Bàng đoạn 2 | C7: Chợ Quán + Bình Tây + Bình Tiên | D7: Góc Bến Bãi Sậy-đường Vạn Tượng | E7: Phạm Đình Hổ | F7: 726 | G7: 2
A8: 3 | B8: Rạch Hàng Bàng đoạn 3 | C8: Bình Tây + Bình Tiên | D8: Minh Phụng | E8: Kênh Tân Hóa- Lò Gốm | F8: 267 | G8: 2.9
A9: 4 | B9: Rạch Bàu Trâu | C9: Phú Thạnh + Phú Lâm | D9: Cuối kênh Hiệp Tân | E9: Kênh Tân Hóa | F9: 1577 | G9: 7
A10: 5 | B10: Rạch Ruột Ngựa đoạn 2 | C10: Bình Phú + Phú Định | D10: Giao rạch Ruột Ngựa - rạch Nhảy | E10: Cầu Phú Định | F10: 814 | G10: 42.8
A11: 6 | B11: Rạch Nhảy | C11: Bình Phú, An Lạc | D11: Rạch Liên khu 3-4 | E11: Giao rạch Ruột Ngựa - rạch Nhảy | F11: =1540+540 -> 2080 | G11: 7,2-21,7
A12: 7 | B12: Rạch Nhỏ (Bà Lựu nối dài) | C12: Phú Định + An Lạc | D12: Đường An Dương Vương | E12: Giao Rạch Ruột Ngựa | F12: 730 | G12: 7.1
A13: 8 | B13: Rạch Bà Tàng - Cầu Sập | C13: Bình Đông + Bình Hưng | D13: Kênh Đôi | E13: Sông Cần Giuộc | F13: 4500
A14: 9 | B14: Rạch Tư Dinh | C14: Tân Hưng | D14: Rạch Đỉa | E14: Rạch Ông Lớn | F14: 1028 | G14: 41-86
A15: 10 | B15: Rạch Ông Tư Dinh | C15: Tân Hưng | D15: Rạch Bàng | E15: Rạch Ông Lớn | F15: 1150 | G15: 41-86 | I15: Bổ sung
A16: 11 | B16: Rạch Bà Lựu (rạch Năng) | C16: Phú Định + An Lạc | D16: Hồ Học Lãm | E16: An Dương Vương | F16: 430 | G16: 3-8
A17: 12 | B17: Sông Phướng | C17: Tân Nhựt + Tân Tạo | D17: Kênh C | E17: Sông Cái Trung | F17: 1700 | G17: 6-8
A18: 13 | B18: Sông Cái Trung | C18: Tân Nhựt + Tân Tạo | D18: Sông Phướng (Bình Tân) | E18: Sông Chợ Đệm (Bình Chánh) | F18: =2294+2800 -> 5094 | G18: 8-40
A19: 14 | B19: Kênh 19/5 | C19: Bình Hưng Hòa + Tân Sơn Nhì + Tây Thạnh | D19: Gần số 243 đường Hai Sáu Tháng Ba | E19: Kênh Tham Lương (Giao đường CN5 - CN3) | F19: 3650 | G19: 10
A20: 15 | B20: Rạch thoát nước ranh quận Bình Tân - Quận 8 | C20: Phú Định + An Lạc | D20: Chung cư Ehome 3 | E20: Tham Lương - Bến Cát - Vàm Nước Lên | F20: 690 | G20: 4,8
A21: 16 | B21: Rạch Lăng 2 | C21: An Nhơn + Bình Lợi Trung | D21: Cầu Đen đường sắt | E21: Kênh Tham Lương | F21: 1420 | G21: 23
A22: 17 | B22: Rạch Lăng 1 | C22: Phường Bình Lợi Trung | D22: Rạch Lăng 2 | E22: Cầu Đen đường sắt | F22: 347 | G22: 5.2
A23: 18 | B23: Rạch Lăng đoạn 2 | C23: Bình Lợi Trung | D23: Số 341/1 Nguyễn Xí - P.13 (gần giao lộ Nguyễn Xí - Phạm Văn Đồng) | E23: Cầu Băng Ky (Nơ Trang Long) | F23: 980 | G23: 8.6 | I23: Bổ sung
A24: 19 | B24: Rạch Lăng đoạn 1 | C24: Bình Thạnh + Bình Lợi Trung | D24: Giao Rạch Tam Vàm Tắc - Rạch Bà Láng) | E24: Cầu Băng Ky (Nơ Trang Long) | F24: 1023 | G24: 26.6
A25: 20 | B25: Rạch Tam Vàm Tắc | C25: Phường Bình Thạnh | D25: Giao rạch Lăng đoạn 1- rạch Bà Láng | E25: Ngã 3 Bình Lợi-Bình Triệu | F25: 522 | G25: 40.2
A26: 21 | B26: Sông Bình Triệu (Hữu Tắc) | C26: Phường Bình Lợi Trung + Phường Bình Thạnh | D26: Ngã 3 Bình Lợi-Bình Triệu | E26: Sông Sài Gòn | F26: 745 | G26: 42.4
A27: 22 | B27: Rạch Xếp Sâu đoạn 1 | C27: An Hội Đông + Thới An | D27: Kênh Tham Lương | E27: Thửa đất số 12, tờ bản đồ số 1, phường 15 Gò Vấp | F27: 1440 | G27: 8-20
A28: 23 | B28: Rạch Xếp Sâu đoạn 2 | C28: An Hội Đông + Thới An | D28: Kênh Tham Lương | E28: Thửa đất số 1, tờ bản đồ số 2, phường 15 Gò Vấp | F28: 200 | G28: 8
A29: 24 | B29: Kênh Trần Quang Cơ | C29: Tân Thới Hiệp + Thới An + Đông Thạnh | D29: Đường Nguyễn Ảnh Thủ | E29: Ngã ba sông Đá Hàn | F29: 5500 | G29: 10-45 | H29: Tuyến 02 chức năng tiêu thoát nước, sản xuất nông nghiệp (Phối hợp quản lý) | I29: Phối hợp quản lý
A30: 25 | B30: Rạch Cầu Dừa | C30: Thới An + Đông Thạnh | D30: Từ kênh Trần Quang Cơ | E30: Rạch Bến Đá | F30: 1100
A31: 26 | B31: Kênh Ranh | C31: Bà Điểm + Vĩnh Lộc | D31: Đoạn 1: từ đường Dương Công Khi Đoạn 2: từ Kênh Trung Ương | E31: Kênh Liên Vùng | F31: 2400 | G31: 1,5-4,5
A32: 27 | B32: Rạch Bồ Đề | C32: Bình Đông + Bình Hưng | D32: Sông Hiệp Ân | E32: Quốc lộ 50 | F32: 1060 | G32: 20-25
A33: 28 | B33: Rạch Đầm Sen | C33: Bình Thới | D33: Đường Giác Viên | E33: Kênh Tân Hóa | F33: 256 | G33: 11.8
A34: 29 | B34: Kênh Lương Bèo | C34: Tân Tạo | D34: Đường số 40 | E34: Tham Lương - Bến Cát - Vàm Nước Lên | F34: 1880 | G34: 8.1
A35: 30 | B35: Kênh Mười Xà | C35: An Lạc | D35: Đường Hồ Học Lãm | E35: Tham Lương - Bến Cát - Vàm Nước Lên | F35: 700 | G35: 2.8
A36: 31 | B36: Kênh Nước Đen | C36: Bình Hưng Hoà | D36: Cửa xả cống hộp Kênh Nước Đen (trước Trạm xử lý Bình Hưng Hòa) | E36: Tham Lương - Bến Cát - Vàm Nước Lên | F36: 1480 | G36: 7
A37: 32 | B37: Rạch Bà Láng đoạn 1 | C37: Bình Thạnh | D37: Ngã 3 rạch Cầu Sơn - Bà Láng | E37: Cửa xả cầu Bùi Đình Tuý | F37: 631 | G37: 24
A38: 33 | B38: Rạch Bà Láng đoạn 2 | C38: Bình Thạnh | D38: Ngã 3 rạch Cầu Sơn - Bà Láng | E38: Cửa xả Cầu Mới đường Bạch Đằng | F38: 651 | G38: 28
A39: 34 | B39: Rạch Bà Láng đoạn 3 | C39: Bình Thạnh | D39: Ngã 3 rạch Bến Bồi - Bà Láng | E39: Cửa xả cầu Chu Văn An | F39: 312 | G39: 10.8
A40: 35 | B40: Rạch Bà Láng đoạn 4 | C40: Bình Thạnh | D40: Cửa xả cầu Chu Văn An | E40: Cửa xả cầu Bùi Đình Tuý | F40: 640 | G40: 8.8
...

Sheet PL3. So NNMT-Tuoi tieu SXNN
A1: PHỤ LỤC 3 DANH MỤC CÁC TUYẾN SÔNG, SUỐI, KÊNH, RẠCH CÓ CHỨC NĂNG TƯỚI TIÊU PHỤC VỤ SẢN XUẤT NÔNG NGHIỆP ĐI QUA ĐỊA GIỚI HÀNH CHÍNH TỪ 02 PHƯỜNG - XÃ TRỞ LÊN, CÁC HỆ THỐNG CÔNG TRÌNH THỦY LỢI, CÁC TUYẾN TRỤC CHÍNH THUỘC THẨM QUYỀN QUẢN LÝ CỦA ỦY BAN NHÂN DÂN THÀNH PHỐ HỒ CHÍ MINH PHÂN CẤP CHO SỞ NÔNG NGHIỆP VÀ MÔI TRƯỜNG QUẢN LÝ, KHAI THÁC (Kèm theo Quyết định số 39/QĐ-UBND ngày 25 tháng 6 năm 2026 của Ủy ban nhân dân Thành phố Hồ Chí Minh)
A2: STT | B2: Tên sông, suối, kênh, rạch | C2: Địa điểm (phường -xã) | D2: Đơn vị được phân cấp quản lý | E2: Lý trình | G2: Quy mô | I2: Ghi chú
E3: Điểm đầu | F3: Điểm cuối | G3: Dài (m) | H3: Rộng (m)
A4: Tổng cộng | G4: =G5+G929 -> 2106258
A5: A. HỆ THỐNG CÔNG TRÌNH THỦY LỢI | G5: =G6+G870+G893 -> 1109990
A6: A1 | B6: KHU VỰC TRUNG TÂM | G6: =SUM(G8:G869) -> 1012540
A7: I | B7: Hệ thống công trình thủy lợi Hóc Môn - Bắc Bình Chánh
A8: 1 | B8: Kênh Trung Ương | C8: Xuân Thới Sơn - Bà Điểm - Vĩnh Lộc - Tân Vĩnh Lộc | D8: Sở Nông nghiệp và Môi trường | E8: Từ Trạm bơm Tân Thới Nhì | F8: Cuối tuyến | G8: 11410
A9: =A8+1 -> 2 | B9: Kênh Liên Vùng | C9: Bà Điểm - Vĩnh Lộc - Tân Vĩnh Lộc | D9: Sở Nông nghiệp và Môi trường | E9: Đường Nguyễn Văn Bứa. | F9: Kênh AH-KC | G9: 9500 | H9: 14-24
A10: =A9+1 -> 3 | B10: Kênh Ranh Long An | C10: Xuân Thới Sơn - Vĩnh Lộc - Tân Vĩnh Lộc - Bình Lợi | D10: Sở Nông nghiệp và Môi trường | E10: Kênh TK7 | F10: Kênh Rau Răm | G10: 15850 | H10: 13-24
A11: =A10+1 -> 4 | B11: Kênh dẫn TB Tân Thới Nhì | C11: Xuân Thới Sơn | D11: Sở Nông nghiệp và Môi trường | E11: Từ cầu An hạ | F11: Trạm bơm TTN | G11: 2285 | H11: 15-20
A12: =A11+1 -> 5 | B12: Kênh AH-KC | C12: xã Tân Vĩnh Lộc + Phường Tân Tạo | D12: Sở Nông nghiệp và Môi trường | E12: Kênh An Hạ | F12: Cầu Tân Tạo | G12: 7583 | H12: 25-35
A13: =A12+1 -> 6 | B13: Kênh A | C13: Tân Vĩnh Lộc - Bình Lợi | D13: Sở Nông nghiệp và Môi trường | E13: Kênh AH-KC | F13: Kênh Xáng Ngang | G13: 6034 | H13: 17-25
A14: =A13+1 -> 7 | B14: Kênh B | C14: Tân Vĩnh Lộc - Bình Lợi | D14: Sở Nông nghiệp và Môi trường | E14: Kênh AH-KC | F14: Kênh Xáng Ngang | G14: 7500 | H14: 17-25
A15: =A14+1 -> 8 | B15: Kênh C | C15: xã Bình Lợi + phường Tân Tạo + xã Tân Nhựt | D15: Sở Nông nghiệp và Môi trường | E15: Từ Cầu Tân Tạo | F15: Kênh Xáng Ngang | G15: 7817 | H15: 25-35
A16: =A15+1 -> 9 | B16: Kênh NT3 | C16: Vĩnh Lộc - Tân Vĩnh Lộc | D16: Sở Nông nghiệp và Môi trường | E16: Kênh Liên Vùng | F16: Cuối tuyến | G16: 1400 | H16: 13
A17: =A16+1 -> 10 | B17: Kênh NT4 | C17: Vĩnh Lộc | D17: Sở Nông nghiệp và Môi trường | E17: Kênh Liên Vùng | F17: Cuối tuyến | G17: 600 | H17: 14
A18: =A17+1 -> 11 | B18: Kênh NT5 | C18: Vĩnh Lộc | D18: Sở Nông nghiệp và Môi trường | E18: Kênh Liên Vùng | F18: Cuối tuyến | G18: 650 | H18: 14
A19: =A18+1 -> 12 | B19: Kênh NT6 | C19: Vĩnh Lộc | D19: Sở Nông nghiệp và Môi trường | E19: Kênh Liên Vùng | F19: Cuối tuyến | G19: 700 | H19: 15
A20: =A19+1 -> 13 | B20: Kênh NT7 | C20: Vĩnh Lộc | D20: Sở Nông nghiệp và Môi trường | E20: Kênh Liên Vùng | F20: Cuối tuyến | G20: 725 | H20: 12
A21: =A20+1 -> 14 | B21: Kênh NT8 | C21: Bà Điểm | D21: Sở Nông nghiệp và Môi trường | E21: Kênh Liên Vùng | F21: Cuối tuyến | G21: 670 | H21: 12
A22: =A21+1 -> 15 | B22: Kênh NT8a | C22: Bà Điểm | D22: Sở Nông nghiệp và Môi trường | E22: Kênh Liên Vùng | F22: Cuối tuyến | G22: 675 | H22: 12
A23: =A22+1 -> 16 | B23: Kênh NT9 | C23: Bà Điểm | D23: Sở Nông nghiệp và Môi trường | E23: Kênh Liên Vùng | F23: Cuối tuyến | G23: 425 | H23: 12
A24: =A23+1 -> 17 | B24: Kênh NT9a | C24: Bà Điểm | D24: Sở Nông nghiệp và Môi trường | E24: Kênh Liên Vùng | F24: Cuối tuyến | G24: 770 | H24: 12
A25: =A24+1 -> 18 | B25: Kênh NT10a | C25: Bà Điểm | D25: Sở Nông nghiệp và Môi trường | E25: Kênh Liên Vùng | F25: Cuối tuyến | G25: 575 | H25: 12
A26: =A25+1 -> 19 | B26: Kênh T15B | C26: Tân Vĩnh Lộc | D26: Sở Nông nghiệp và Môi trường | E26: Kênh B | F26: Cuối tuyến | G26: 1654 | H26: 12
A27: =A26+1 -> 20 | B27: Kênh L8 (T16) | C27: Tân Vĩnh Lộc | D27: Sở Nông nghiệp và Môi trường | E27: Kênh AH-KC | F27: Cuối tuyến | G27: 1200 | H27: 12
A28: =A27+1 -> 21 | B28: Kênh AH13 (T10) | C28: Bà Điểm | D28: Sở Nông nghiệp và Môi trường | E28: Kênh An Hạ | F28: Kênh Liên Vùng | G28: 1735 | H28: 20-22
A29: =A28+1 -> 22 | B29: Kênh AH15 (T9) | C29: Bà Điểm | D29: Sở Nông nghiệp và Môi trường | E29: Kênh An Hạ | F29: Kênh Liên Vùng | G29: 1725 | H29: 12
A30: =A29+1 -> 23 | B30: Kênh AH17 (T8) | C30: Bà Điểm | D30: Sở Nông nghiệp và Môi trường | E30: Kênh An Hạ | F30: Kênh Liên Vùng | G30: 1772 | H30: 12
A31: =A30+1 -> 24 | B31: Kênh AH19 (T7) | C31: Bà Điểm - Vĩnh Lộc | D31: Sở Nông nghiệp và Môi trường | E31: Kênh An Hạ | F31: Kênh Liên Vùng | G31: 1792 | H31: 12
A32: =A31+1 -> 25 | B32: Kênh AH21 (T6) | C32: Vĩnh Lộc | D32: Sở Nông nghiệp và Môi trường | E32: Kênh An Hạ | F32: Kênh Liên Vùng | G32: 1812 | H32: 12
A33: =A32+1 -> 26 | B33: Kênh AH23 (T5) | C33: Vĩnh Lộc - Tân Vĩnh Lộc | D33: Sở Nông nghiệp và Môi trường | E33: Kênh An Hạ | F33: Kênh Liên Vùng | G33: 1840 | H33: 12
A34: =A33+1 -> 27 | B34: Kênh AH25 (T4) | C34: Vĩnh Lộc - Tân Vĩnh Lộc | D34: Sở Nông nghiệp và Môi trường | E34: Kênh An Hạ | F34: Kênh Liên Vùng | G34: 1837 | H34: 12
A35: =A34+1 -> 28 | B35: Kênh AH27 (T3) | C35: Vĩnh Lộc - Tân Vĩnh Lộc | D35: Sở Nông nghiệp và Môi trường | E35: Kênh An Hạ | F35: Kênh Liên Vùng | G35: 1830 | H35: 12
A36: =A35+1 -> 29 | B36: Kênh AH29 (T2) | C36: Tân Vĩnh Lộc | D36: Sở Nông nghiệp và Môi trường | E36: Kênh An Hạ | F36: Kênh Liên Vùng | G36: 1775 | H36: 12
A37: =A36+1 -> 30 | B37: Kênh AH33 (T0) | C37: Tân Vĩnh Lộc | D37: Sở Nông nghiệp và Môi trường | E37: Kênh An Hạ | F37: Cuối tuyến | G37: 4875 | H37: 15-18
A38: =A37+1 -> 31 | B38: Kênh AH35 (T11) | C38: Tân Vĩnh Lộc | D38: Sở Nông nghiệp và Môi trường | E38: Kênh AH-KC | F38: Kênh T0 | G38: 1250 | H38: 12
A39: =A38+1 -> 32 | B39: Kênh AH37 (T12) | C39: Tân Vĩnh Lộc | D39: Sở Nông nghiệp và Môi trường | E39: Kênh AH-KC | F39: Kênh T0 | G39: 1300 | H39: 12
A40: =A39+1 -> 33 | B40: Kênh AH39 (T13) | C40: Tân Vĩnh Lộc | D40: Sở Nông nghiệp và Môi trường | E40: Kênh T14 | F40: Kênh T0 | G40: 1300 | H40: 12
...

Sheet PL4. So NNMT-ho dap
A1: PHỤ LỤC 4 DANH MỤC CÁC HỒ, ĐẬP CÓ CHỨC NĂNG TƯỚI TIÊU PHỤC VỤ SẢN XUẤT NÔNG NGHIỆP, CẤP NƯỚC SINH HOẠT, ĐIỀU TIẾT LŨ CÓ PHẠM VI ẢNH HƯỞNG TRÊN ĐỊA BÀN TỪ 02 PHƯỜNG - XÃ TRỞ LÊN THUỘC THẨM QUYỀN QUẢN LÝ CỦA ỦY BAN NHÂN DÂN THÀNH PHỐ HỒ CHÍ MINH PHÂN CẤP CHO SỞ NÔNG NGHIỆP VÀ MÔI TRƯỜNG QUẢN LÝ, KHAI THÁC
A2: (Kèm theo Quyết định số 39/QĐ-UBND ngày 25 tháng 6 năm 2026 của Ủy ban nhân dân Thành phố Hồ Chí Minh)
A4: STT | B4: Tên hồ, đập | C4: Địa điểm (phường -xã) | D4: Quy mô thiết kế | I4: Ghi chú
D5: Dung tích toàn bộ (triệu m3) | E5: Chiều cao đập chính (m) | F5: Chiều dài đập chính (m) | G5: Lưu lượng xả tràn, xã lũ (m3/s) | H5: Loại công trình
A6: A | B6: Hồ
A7: 1 | B7: Hồ Sông Ray | C7: Xã Xuân Sơn, xã Hòa Hội, xã Bàu Lâm, xã Sông Ray | D7: 215.36 | E7: 34 | F7: 1930 | G7: 2641 | H7: Hồ lớn
A8: 2 | B8: Hồ Đá Đen | C8: Xã Ngãi Giao, xã Kim Long, xã Châu Pha, Phường Tân Thành | D8: 33.4 | E8: 22.5 | F8: 1258 | G8: 400.84
A9: 3 | B9: Hồ Suối Giàu | C9: Xã Xuân Sơn, xã Nghĩa Thành | D9: 12.2 | E9: 23.8 | F9: 600 | G9: 67.7
A10: 4 | B10: Hồ Đá Bàng | C10: Xã Nghĩa Thành, xã Đất Đỏ | D10: 11.35 | E10: 14.2 | F10: 941 | G10: 80.89
A11: 5 | B11: Hồ Tầm Bó | C11: Xã Kim Long, xã Bình Giã | D11: 5.85 | E11: 19.2 | F11: 680 | G11: 40
A12: 6 | B12: Hồ Lồ Ồ | C12: Xã Xuân Sơn, xã Đất Đỏ | D12: 6 | E12: 15.6 | F12: 600 | G12: 162.9
A13: 7 | B13: Hồ Xuyên Mộc | C13: Xã Hồ Tràm | D13: 4.5 | E13: 10.5 | F13: 1022 | G13: 6
A14: 8 | B14: Hồ Suối Các | C14: Xã Hòa Hiệp | D14: 4.3 | E14: 12.43 | F14: 1220 | G14: 40.44
A15: 9 | B15: Hồ Gia Hoét I | C15: Xã Bình Giã | D15: 4 | E15: 21.3 | F15: 809 | G15: 45.09
A16: 10 | B16: Hồ Châu Pha | C16: Xã Châu Pha, Phường Tân Thành | D16: 3.52 | E16: 7.5 | F16: 1010 | G16: 64.13
A17: 11 | B17: Hồ Kim Long | C17: Xã Kim Long | D17: 3.78 | E17: 21 | F17: 1000 | G17: 45.5
A18: 12 | B18: Hồ Sông Hỏa | C18: Xã Hòa Hội, xã Xuyên Mộc | D18: 2.22 | E18: 12 | F18: 1593 | G18: 152.1
A19: 13 | B19: Hồ Đá Bàn | C19: Xã Bắc Tân Uyên | D19: 5.887 | E19: 14 | F19: 400 | G19: 10.06
A20: 14 | B20: Hồ Cần Nôm | C20: Xã Thanh An | D20: 7.487 | E20: 12 | F20: 800 | G20: 20.75
A21: 15 | B21: Hồ Suối Môn | C21: Xã Đất Đỏ | D21: 1.6 | E21: 8.7 | F21: 1105 | G21: 18 | H21: Hồ vừa
A22: 16 | B22: Hồ Núi Nhan | C22: Xã Ngãi Giao, xã Kim Long | D22: 1.12 | E22: 13 | F22: 345 | G22: 3.6
A23: 17 | B23: Hồ Dốc Nhàn | C23: Xã Thường Tân | D23: 0.545 | E23: 9 | F23: 192.5
A24: 18 | B24: Hồ Gia Hoét II | C24: Xã Bình Giã | D24: 0.067 | F24: 6 | H24: Hồ nhỏ
A25: 19 | B25: Hồ Suối Sao | C25: Xã Bình Giã | D25: 0.107 | F25: 7.2
A26: 20 | B26: Hồ Suối Đôi I | C26: Xã Bình Giã | D26: 0.165 | E26: 251 | F26: 93
A27: 21 | B27: Hồ Từ Vân I | C27: Phường Bến Cát | D27: 0.309 | E27: 350 | F27: 5.1
A28: 22 | B28: Hồ Từ Vân II | C28: Phường Bến Cát | D28: 0.241 | E28: 332 | F28: 6.35
A29: B | B29: ĐẬP DÂNG
A30: 1 | B30: Đập Sông Dinh I | C30: Phường Bà Rịa, Phường Long Hương, Phường Tam Long
A31: 2 | B31: Đập dâng Sông Ray | C31: Xã Đất Đỏ
A32: 3 | B32: Đập Sông Xoài | C32: Xã Châu Pha, xã Nghĩa Thành
A33: 4 | B33: Đập Suối Sỏi | C33: Phường Tam Long
A34: 5 | B34: Đập Sông Dinh II | C34: Phường Long Hương, Phường Bà Rịa
A35: 6 | B35: Đập Suối Nghệ | C35: Xã Ngãi Giao
A36: 7 | B36: Đập Phước An | C36: Xã Nghĩa Thành
A37: 8 | B37: Đập Bà | C37: Phường Tam Long, Xã Đất Đỏ
A38: 9 | B38: Đập dâng Cầu Mới | C38: Xã Hồ Tràm
A39: 10 | B39: Đập Ông Hựu | C39: Phường Tân Uyên
A40: 11 | B40: Đập Thị Tính (Đập Hàng Nù) | C40: xã Long Hòa, xã Thanh An

Sheet PL5. Phuong xa-song kenh rach
A1: PHỤ LỤC 5 DANH MỤC CÁC TUYẾN KÊNH, RẠCH CÓ CHỨC NĂNG TIÊU THOÁT NƯỚC, TƯỚI TIÊU PHỤC VỤ SẢN XUẤT NÔNG NGHIỆP THUỘC THẨM QUYỀN QUẢN LÝ CỦA ỦY BAN NHÂN DÂN THÀNH PHỐ HỒ CHÍ MINH PHÂN CẤP CHO ỦY BAN NHÂN DÂN CÁC PHƯỜNG, XÃ QUẢN LÝ (Kèm theo Quyết định số 39/QĐ-UBND ngày 25 tháng 6 năm 2026 của Ủy ban nhân dân Thành phố Hồ Chí Minh)
A2: STT | B2: Tên sông, kênh, rạch | C2: Địa điểm (phường, xã, đặc khu) | D2: Phân cấp quản lý | E2: Lý trình | G2: Quy mô
E3: Điểm đầu | F3: Điểm cuối | G3: Dài (m) | H3: Rộng (m)
A4: Tổng cộng: | G4: =G5+G1234 -> 3782784
A5: A. DANH MỤC CÁC TUYẾN KÊNH, RẠCH CÓ CHỨC NĂNG TIÊU THOÁT NƯỚC PHÂN CẤP CHO ỦY BAN NHÂN DÂN CÁC PHƯỜNG, XÃ QUẢN LÝ THEO ĐỊA GIỚI HÀNH CHÍNH | G5: =G6+G959+G1159 -> 1472002.9
A6: I. KHU VỰC TRUNG TÂM | G6: =SUM(G7:G958) -> 706023.88
A7: 1 | B7: Rạch Bà Đô | C7: Phường Chợ Quán | D7: ="UBND "&C7 -> UBND Phường Chợ Quán | E7: Cống thoát nước băng đường Võ Văn Kiệt | F7: Kênh Tàu Hủ | G7: 25 | H7: 2,5
A8: 2 | B8: Rạch Bà Miêng nhánh 1 | C8: Phường An Hội Đông | D8: ="UBND "&C8 -> UBND Phường An Hội Đông | E8: Cuối hẻm 730 Lê Đức Thọ | F8: Rạch Bà Miêng | G8: 390 | H8: 2.4
A9: 3 | B9: Rạch Chùa Chiêm Phước | C9: Phường An Hội Đông | D9: ="UBND "&C9 -> UBND Phường An Hội Đông | E9: Số nhà 884/39 Lê Đức Thọ, phường 15 | F9: Kênh Tham Lương | G9: 340 | H9: 3.7
A10: 4 | B10: Rạch khu phố 8, phường 15 | C10: Phường An Hội Đông | D10: ="UBND "&C10 -> UBND Phường An Hội Đông | E10: Kênh Tham Lương | F10: Hẻm 114 Tô Ngọc Vân | G10: 310 | H10: 6
A11: 5 | B11: Rạch Cầu Cụt nhánh 1 | C11: Phường An Hội Tây | D11: ="UBND "&C11 -> UBND Phường An Hội Tây | E11: Số nhà 120/57/55 đường số 59, Phường 14. | F11: Rạch Cầu Cụt | G11: 127 | H11: 1.5
A12: 6 | B12: Rạch Cầu Cụt | C12: Phường An Hội Tây | D12: ="UBND "&C12 -> UBND Phường An Hội Tây | E12: Sau lưng trại gia cầm (148/11/54, đường số 59, phường 14) | F12: Kênh Tham Lương | G12: 846 | H12: 6
A13: 7 | B13: Rạch Nguyễn Văn Hưởng 2 | C13: Phường An Khánh | D13: ="UBND "&C13 -> UBND Phường An Khánh | E13: Đường Nguyễn Văn Hưởng | F13: Sông Sài Gòn | G13: 105 | H13: 6
A14: 8 | B14: Rạch Nguyễn Văn Hưởng 3 | C14: Phường An Khánh | D14: ="UBND "&C14 -> UBND Phường An Khánh | E14: Đường Nguyễn Văn Hưởng | F14: Sông Sài Gòn | G14: 90 | H14: 6
A15: 9 | B15: Rạch Nguyễn Văn Hưởng 4 | C15: Phường An Khánh | D15: ="UBND "&C15 -> UBND Phường An Khánh | E15: Đường Nguyễn Văn Hưởng | F15: Sông Sài Gòn | G15: 88 | H15: 12
A16: 10 | B16: Rạch Nguyễn Văn Hưởng 5 | C16: Phường An Khánh | D16: ="UBND "&C16 -> UBND Phường An Khánh | E16: Đường Nguyễn Văn Hưởng | F16: Sông Sài Gòn | G16: 87 | H16: 10
A17: 11 | B17: Rạch Dừa (Nguyễn Văn Hưởng 8) | C17: Phường An Khánh | D17: ="UBND "&C17 -> UBND Phường An Khánh | E17: Hẻm 97 | F17: Sông Sài Gòn | G17: 570 | H17: 25
A18: 12 | B18: Rạch Ngo (Rạch Cầu Phao) | C18: Phường An Khánh | D18: ="UBND "&C18 -> UBND Phường An Khánh | E18: Ngã ba rạch Cầu Ông Cậy | F18: Ngã 3 sông Sài Gòn | G18: 2200 | H18: 15
A19: 13 | B19: Rạch Đá Đỏ | C19: Phường An Khánh | D19: ="UBND "&C19 -> UBND Phường An Khánh | E19: Ngã 3 sông Sài Gòn | F19: Cầu Bê tông cốt thép | G19: 1600 | H19: 20
A20: 14 | B20: Rạch Thảo Điền | C20: Phường An Khánh | D20: ="UBND "&C20 -> UBND Phường An Khánh | E20: Hội trường KP1 | F20: Sông Sài Gòn | G20: 1100 | H20: 20
A21: 15 | B21: Rạch Ông Chua | C21: Phường An Khánh | D21: ="UBND "&C21 -> UBND Phường An Khánh | E21: Đường Quốc Hương | F21: Đường Song hành Xa lộ Hà Nội | G21: 450 | H21: 2-6
A22: 16 | B22: Rạch Ông Hóa | C22: Phường An Khánh | D22: ="UBND "&C22 -> UBND Phường An Khánh | E22: Hội trường KP6 | F22: Sông Sài Gòn | G22: 650 | H22: 10
A23: 17 | B23: Rạch Ông Dí | C23: Phường An Khánh | D23: ="UBND "&C23 -> UBND Phường An Khánh | E23: Đường số 61 | F23: Đường Nguyễn Văn Hưởng | G23: 401 | H23: 10
A24: 18 | B24: Rạch Khu Phố 1 | C24: Phường An Khánh | D24: ="UBND "&C24 -> UBND Phường An Khánh | E24: Dự án Phát triển nhà Thủ Đức | F24: Sông Sài Gòn | G24: 269 | H24: 2-10
... A44: 38 | B44: Rạch Ruột Ngựa nhánh 1 (Kênh Năm Sao) | C44: Phường An Lạc | D44: ="UBND "&C44 -> UBND Phường An Lạc | E44: Hẻm số 27/36/75/12/4 đường Bùi Tư Toàn | F44: Rạch Ruột Ngựa | G44: 430 | H44: 3-8
A45: 39 | B45: Rạch Khu phố 3-4 (nhánh 1) | C45: Phường An Lạc | D45: ="UBND "&C45 -> UBND Phường An Lạc | E45: Rạch khu phố 3-4 | F45: Hẻm số 92/10 | G45: 320 | H45: 3
A46: 40 | B46: Rạch Khu phố 3-4 (nhánh 2) | C46: Phường An Lạc | D46: ="UBND "&C46 -> UBND Phường An Lạc | E46: Rạch khu phố 3-4 | F46: Hẻm số 50/1/57 | G46: 174 | H46: 3
A47: 41 | B47: Nhánh 2 Rạch Nhảy | C47: Phường An Lạc | D47: ="UBND "&C47 -> UBND Phường An Lạc | E47: Rạch Nhảy | F47: Khu tái định cư Lý Chiêu Hoàng | G47: 160 | H47: 5-15
A48: 42 | B48: Kênh Hai Nghiệp | C48: Phường An Lạc | D48: ="UBND "&C48 -> UBND Phường An Lạc | E48: Kênh Tham Lương - Bến Cát - rạch Nước Lên | F48: cuối tuyến (nhà dân hiện hữu) | G48: 150 | H48: 8
A49: 43 | B49: Kênh Nội Đồng (cặp hẻm 130 đường Lê Tấn Bê) | C49: Phường An Lạc | D49: ="UBND "&C49 -> UBND Phường An Lạc | E49: Đường Lê Tấn Bê | F49: Rạch Nước Lên | G49: 160 | H49: 3-7
A50: 44 | B50: Rạch Chín Xiểng | C50: Phường An Nhơn | D50: ="UBND "&C50 -> UBND Phường An Nhơn | E50: 80/61A Dương Quảng Hàm, phường 5 | F50: Rạch Làng Lớn | G50: 783 | H50: 10
A51: 45 | B51: Rạch Dừa (đoạn mương hở) | C51: Phường An Nhơn | D51: ="UBND "&C51 -> UBND Phường An Nhơn | E51: Dương Quảng Hàm | F51: Kênh Tham Lương | G51: 670 | H51: 17.5
A52: 46 | B52: Rạch Ông Bàu nhánh 1 | C52: Phường An Nhơn | D52: ="UBND "&C52 -> UBND Phường An Nhơn | E52: Số 246/32/7 Dương Quảng hàm, phường 6 | F52: Ngã ba giao rạch Ông Bàu | G52: 127 | H52: 7
A53: 47 | B53: Rạch Ông Tổng | C53: Phường An Nhơn | D53: ="UBND "&C53 -> UBND Phường An Nhơn | E53: Số 234/59 Lê Đức Thọ, phường 6 (ngã ba giao rạch Ông Tổng nhánh 1 và 3) | F53: Kênh Tham Lương | G53: 555 | H53: 20
A54: 48 | B54: Rạch Ông Tổng nhánh 1 | C54: Phường An Nhơn | D54: ="UBND "&C54 -> UBND Phường An Nhơn | E54: Số 234/43 Lê Đức Thọ, phường 6 | F54: Rạch Ông Tổng (ngã ba giao với rạch Ông Tổng và Ông Tổng nhánh 3) | G54: 288 | H54: 6.5
A55: 49 | B55: Rạch Ông Tổng nhánh 2 | C55: Phường An Nhơn | D55: ="UBND "&C55 -> UBND Phường An Nhơn | E55: Cuối hẻm 496/1 Dương Quảng Hàm, phường 6 | F55: Rạch Ông Tổng nhánh 1 | G55: 58 | H55: 3.9
A56: 50 | B56: Rạch Ông Tổng nhánh 3 | C56: Phường An Nhơn | D56: ="UBND "&C56 -> UBND Phường An Nhơn | E56: Số 496/15/20Dương Quảng Hàm, phường 7 | F56: Rạch Ông Tổng (ngã ba giao với rạch Ông Tổng và Ông Tổng nhánh 1) | G56: 180 | H56: 6
A57: 51 | B57: Rạch Làng Lớn | C57: Phường An Nhơn | D57: ="UBND "&C57 -> UBND Phường An Nhơn | E57: Đường Dương Quảng Hàm | F57: Kênh Tham Lương | G57: 360 | H57: 11
A58: 52 | B58: Rạch Cụt | C58: Phường An Nhơn | D58: ="UBND "&C58 -> UBND Phường An Nhơn | E58: Hẻm 110/39 đường số 30, phường 6 | F58: Kênh Tham Lương | G58: 320 | H58: 14
A59: 53 | B59: Nhánh sông Sài Gòn 8 | C59: Phường An Phú Đông | D59: ="UBND "&C59 -> UBND Phường An Phú Đông | E59: Sông Sài Gòn | F59: Sông Sài Gòn | G59: 900 | H59: 15
...

Sheet PL6. Phuong xa-Ho dap phan
A1: PHỤ LỤC 6 DANH MỤC CÁC HỒ, ĐẬP CÓ CHỨC NĂNG TƯỚI TIÊU PHỤC VỤ SẢN XUẤT NÔNG NGHIỆP, CẤP NƯỚC SINH HOẠT THUỘC THẨM QUYỀN QUẢN LÝ CỦA ỦY BAN NHÂN DÂN THÀNH PHỐ HỒ CHÍ MINH PHÂN CẤP CHO ỦY BAN NHÂN DÂN CÁC PHƯỜNG, XÃ QUẢN LÝ, KHAI THÁC (Kèm theo Quyết định số 39/QĐ-UBND ngày 25 tháng 6 năm 2026 của Ủy ban nhân dân Thành phố Hồ Chí Minh)
A2: STT | B2: Tên hồ, đập | C2: Địa điểm (phường, xã, đặc khu) | D2: Đơn vị được phân cấp quản lý | E2: Quy mô thiết kế | K2: Ghi chú
E3: Dung tích toàn bộ (triệu m3) | F3: Chiều cao đập chính (m) | G3: Chiều dài đập chính (m) | H3: Chiều rộng đập chính (m) | I3: Lưu lượng xả tràn, xã lũ (m3/s) | J3: Loại công trình
A4: A | B4: Hồ
A5: 1 | B5: Hồ Nhà Bè | C5: Phường Tân Thành | D5: Ủy ban nhân dân phường Tân Thành | E5: 0.21 | J5: Hồ nhỏ
A6: 2 | B6: Hồ Suối Đá | C6: Xã Châu Pha | D6: Ủy ban nhân dân xã Châu Pha | E6: 0.78 | F6: 6 | G6: 400 | J6: Hồ vừa
A7: 3 | B7: Hồ Hải Sơn | C7: Phường Tân Phước | D7: Ủy ban nhân dân phường Tân Phước | E7: 0.03
A8: 4 | B8: Hồ Sạn (cạnh Depot Long Bình) | C8: Phường Long Bình | D8: Ủy ban nhân dân phường Long Bình
A9: 5 | B9: Hồ Điều Hòa (KP. Hòa Phú 3) | C9: Phường Bình Dương | D9: UBND Phường Bình Dương
A10: 6 | B10: Hồ Điều Tiết (KP. Phú Tân 3) | C10: Phường Bình Dương | D10: UBND Phường Bình Dương
A11: 7 | B11: Hồ Bàu Úc | C11: Phường Tam Long | D11: Ủy ban nhân dân phường Tam Long | E11: 0.84 | F11: 14 | G11: 594 | J11: Hồ lớn
A12: 8 | B12: Hồ Sở Bông | C12: Xã Phước Hải | D12: Ủy ban nhân dân xã Phước Hải | E12: 0.82 | F12: 6.76 | G12: 1350 | H12: 18.3 | J12: Hồ vừa
A13: 9 | B13: Hồ Bút Thiền | C13: Xã Phước Hải | D13: Ủy ban nhân dân xã Phước Hải | E13: 2.4 | F13: 8.5 | G13: 1850 | H13: 23 | J13: Hồ vừa
A14: 10 | B14: Đập giữ nước khu vực núi Minh Đạm | C14: Xã Phước Hải | D14: Ủy ban nhân dân xã Phước Hải | E14: 0.023 | G14: 8.5
A15: B | B15: Đập
A16: 1 | B16: Đập dâng suối Cầu 4 | C16: Xã Hòa Hiệp | D16: Ủy ban nhân dân xã Hòa Hiệp
A17: 2 | B17: Đập dâng suối Cầu 5 | C17: Xã Hòa Hiệp | D17: Ủy ban nhân dân xã Hòa Hiệp
A18: 3 | B18: Đập dâng suối Cầu 6 | C18: Xã Hòa Hiệp | D18: Ủy ban nhân dân xã Hòa Hiệp
A19: 4 | B19: Đập dâng suối Bang | C19: Xã Hòa Hiệp | D19: Ủy ban nhân dân xã Hòa Hiệp
A20: 5 | B20: Đập dâng suối Xa ác 1 | C20: Xã Bàu Lâm | D20: Ủy ban nhân dân xã Bàu Lâm | F20: 2 | G20: 2 | H20: 2
A21: 6 | B21: Đập dâng suối Xa ác 2 | C21: Xã Bàu Lâm | D21: Ủy ban nhân dân xã Bàu Lâm | F21: 2 | G21: 2 | H21: 2
A22: 7 | B22: Đập dâng suối Xa ác 3 | C22: Xã Bàu Lâm | D22: Ủy ban nhân dân xã Bàu Lâm | F22: 2 | G22: 2 | H22: 2
A23: 8 | B23: Đập dâng suối Xa ác 4 | C23: Xã Bàu Lâm | D23: Ủy ban nhân dân xã Bàu Lâm | F23: 2 | G23: 2 | H23: 2
A24: 9 | B24: Đập dâng suối Xa ác 5 | C24: Xã Bàu Lâm | D24: Ủy ban nhân dân xã Bàu Lâm | F24: 2 | G24: 2 | H24: 2
A25: 10 | B25: Đập dâng trên Kênh T1 (vi trí T1-3) | C25: Xã Bàu Lâm | D25: Ủy ban nhân dân xã Bàu Lâm | F25: 1.5 | G25: 5-10 | H25: 5-10
A26: 11 | B26: Đập dâng trên Kênh T1 (vi trí T1-4) | C26: Xã Bàu Lâm | D26: Ủy ban nhân dân xã Bàu Lâm | F26: 1.5 | G26: 5-10 | H26: 5-10
A27: 12 | B27: Đập dâng Tân Trung | C27: Xã Châu Pha | D27: Ủy ban nhân dân xã Châu Pha | F27: 2.5
A28: 13 | B28: Đập dâng Tân Long | C28: Xã Châu Pha | D28: Ủy ban nhân dân xã Châu Pha | F28: 2.5
A29: 14 | B29: Đập dâng Tân Lễ A | C29: Xã Châu Pha | D29: Ủy ban nhân dân xã Châu Pha | F29: 2.5
A30: 15 | B30: Đập dâng Tân Lễ B | C30: Xã Châu Pha | D30: Ủy ban nhân dân xã Châu Pha | F30: 2.5
A31: 16 | B31: Đập dâng suối Đá 1 | C31: Xã Bình Châu | D31: Ủy ban nhân dân xã Bình Châu | F31: 12 | G31: 2,5 | H31: 3
A32: 17 | B32: Đập dâng suối Đá 2 | C32: Xã Bình Châu | D32: Ủy ban nhân dân xã Bình Châu | F32: 12 | G32: 2,5 | H32: 3
A33: 18 | B33: Đập 6 cửa | C33: Phường Tân Hải | D33: Ủy ban nhân dân phường Tân Hải
A34: 19 | B34: Đập Ông Tĩnh | C34: Phường Tân Hải | D34: Ủy ban nhân dân phường Tân Hải
A35: 20 | B35: Đập Tây Phương | C35: Phường Tân Hải | D35: Ủy ban nhân dân phường Tân Hải
A36: 21 | B36: Đập Rạch Chanh 1 | C36: Phường Tân Hải | D36: Ủy ban nhân dân phường Tân Hải
A37: 22 | B37: Đập Rạch Chanh 2 | C37: Phường Tân Hải | D37: Ủy ban nhân dân phường Tân Hải
A38: 23 | B38: Đập Giao Kèo | C38: Xã Châu Pha | D38: Ủy ban nhân dân xã Châu Pha
A39: 24 | B39: Đập Tầm Phục | C39: Xã Châu Pha | D39: Ủy ban nhân dân xã Châu Pha
A40: 25 | B40: Đập Mù U | C40: Xã Châu Pha | D40: Ủy ban nhân dân xã Châu Pha
...

Sheet PL7. BQL VQG Con Dao
A1: PHỤ LỤC 7 DANH MỤC CÁC TUYẾN SÔNG, SUỐI, KÊNH, RẠCH, HỒ, ĐẬP CÓ CHỨC NĂNG TIÊU THOÁT NƯỚC CHO KHU DÂN CƯ, KHU ĐÔ THỊ, KHU CÔNG NGHIỆP VÀ TƯỚI TIÊU PHỤC VỤ SẢN XUẤT NÔNG NGHIỆP THUỘC THẨM QUYỀN QUẢN LÝ CỦA ỦY BAN NHÂN DÂN THÀNH PHỐ HỒ CHÍ MINH PHÂN CẤP CHO ỦY BAN NHÂN DÂN ĐẶC KHU CÔN ĐẢO QUẢN LÝ, KHAI THÁC (Kèm theo Quyết định số 39/QĐ-UBND ngày 25 tháng 6 năm 2026 của Ủy ban nhân dân Thành phố Hồ Chí Minh)
A2: STT | B2: Tên sông, kênh, rạch, hồ, đập | C2: Địa điểm | D2: Lý trình | F2: Quy mô
D3: Điểm đầu (tọa độ X;Y) | E3: Điểm cuối (tọa độ X;Y) | F3: Dài (m) | G3: Rộng (m) | H3: Ghi chú
A4: I. Danh mục các tuyến sông, kênh, rạch: Tổng cộng 06 tuyến, tổng chiều dài L= 35.000 m
A5: 1 | B5: Suối Bà Hạp | C5: Đặc khu Côn Đảo | D5: Núi Thánh giá (373614.19; 963061.60) | E5: Hồ An Hải (373177.98; 959627.23) | F5: 7900
A6: 2 | B6: Suối Lò Vôi | C6: Đặc khu Côn Đảo | D6: Núi Chúa (375127.33; 963471.82) | E6: Bãi biển Lò vôi (375822.37; 961403.87) | F6: 8300
A7: 3 | B7: Suối Đất Dốc | C7: Đặc khu Côn Đảo | D7: Núi Chúa (375453.67; 963476.53) | E7: Bãi biển Sixsens (376909.46; 962311.22) | F7: 4200
A8: 4 | B8: Suối Ớt | C8: Đặc khu Côn Đảo | D8: Núi Chúa (375946.77; 963638.33) | E8: Bãi Vong (377432.68; 963654.51) | F8: 5200
A9: 5 | B9: Suối Cỏ Ống | C9: Đặc khu Côn Đảo | D9: (678940.09; 963623.12) | E9: (679010.39; 965483.09) | F9: 3900
A10: 6 | B10: Suối Đầm Trầu | C10: Đặc khu Côn Đảo | D10: Núi Chúa (375113.95; 963590.99) | E10: Bãi Đầm Trầu (375387.26; 965476.21) | F10: 5500
A11: II. Danh mục hồ, đập: Tổng cộng 06 hồ | D11: Dung tích toàn bộ (triệu m3) | E11: Chiều dài đập chính/kè bảo vệ (m) | F11: Chiều cao đập chính (m) | G11: Phân loại hồ
A12: 1 | B12: Hồ Đất Dốc | C12: Đặc khu Côn Đảo | D12: 0.17 | E12: 288.25 | F12: 19.7 | G12: Lớn
A13: 2 | B13: Hồ Lò Vôi | C13: Đặc khu Côn Đảo | D13: 0.053 | E13: 1198.84 | G13: Nhỏ
A14: 3 | B14: Hồ Suối Ớt | C14: Đặc khu Côn Đảo | D14: 0.0667 | E14: 114.6 | F14: 9.7
A15: 4 | B15: Hồ An Hải | C15: Đặc khu Côn Đảo | D15: 0.54 | E15: 2726.5 | G15: Vừa
A16: 5 | B16: Hồ Quang Trung I | C16: Đặc khu Côn Đảo | D16: 0.518 | E16: 2222.82
A17: 6 | B17: Hồ Quang Trung II | C17: Đặc khu Côn Đảo | D17: 0.645 | E17: 1737.05 | F17: 6.69

Sheet Tuoi tieu nong nghiep
C1: Phụ lục 3: Danh mục các tuyến kênh, rạch có chức năng tưới tiêu phục vụ sản xuất nông nghiệp, nuôi trồng thủy sản, phát triển rừng và sản xuất muối trên địa bàn Thành phố
C3: (Kèm theo Quyết định số 28/2016/QĐ-UBND ngày 12 tháng 8 năm 2016 của Ủy ban nhân dân Thành phố)
C5: STT | D5: Tên kênh, rạch | E5: Quản lý ngành | F5: Quản lý trực tiếp | G5: Chiều dài (m) | H5: Lý trình | J5: Ghi chú
H6: Điểm đầu | I6: Điểm cuối
C7: Tổng cộng: 1.992 tuyến, tổng chiều dài 2.299.133m | G7: =SUM(G8:G1999) -> 2300403
A8: =A9++A1241+A1291+A1399+A1498+A1824+A1858+A1999 -> 1992 | B8: =SUM(B9:B1999) -> 2300403 | C8: 1 | D8: Kênh C | E8: Sở Nông nghiệp và Phát triển nông thôn | F8: Công ty TNHH MTV QLKTDV Thủy lợi TP | G8: 2500 | H8: Cầu Tân Tạo | I8: Sông Phướng
A9: 1226 | B9: =SUM(G8:G1233) -> 1234244 | C9: 2 | D9: Kênh số 1 (Kênh C3) | E9: Sở Nông nghiệp và Phát triển nông thôn | F9: Công ty TNHH MTV QLKTDV Thủy lợi TP | G9: 1500 | H9: Kênh C | I9: Cuối tuyến
C10: =C9+1 -> 3 | D10: Kênh số 2 (Kênh C5) | E10: Sở Nông nghiệp và Phát triển nông thôn | F10: Công ty TNHH MTV QLKTDV Thủy lợi TP | G10: 2220 | H10: Kênh C | I10: Sông Đập
C11: =C10+1 -> 4 | D11: Kênh số 3 (Kênh C7) | E11: Sở Nông nghiệp và Phát triển nông thôn | F11: Công ty TNHH MTV QLKTDV Thủy lợi TP | G11: 2530 | H11: Kênh C | I11: Đường Nguyễn Cửu Phú
C12: =C11+1 -> 5 | D12: Kênh số 4 (Kênh C9) | E12: Sở Nông nghiệp và Phát triển nông thôn | F12: Công ty TNHH MTV QLKTDV Thủy lợi TP | G12: 2580 | H12: Kênh C | I12: Đường Nguyễn Cửu Phú
C13: =C12+1 -> 6 | D13: Kênh số 5 (Kênh C11) | E13: Sở Nông nghiệp và Phát triển nông thôn | F13: Công ty TNHH MTV QLKTDV Thủy lợi TP | G13: 2470 | H13: Kênh C | I13: Đường Nguyễn Cửu Phú
C14: =C13+1 -> 7 | D14: Nhánh kênh số 3 | E14: Sở Nông nghiệp và Phát triển nông thôn | F14: Công ty TNHH MTV QLKTDV Thủy lợi TP | G14: 300 | H14: Sông Đập | I14: Nguyễn Cữu Phú
C15: =C14+1 -> 8 | D15: Nhánh kênh số 4 | E15: Sở Nông nghiệp và Phát triển nông thôn | F15: Công ty TNHH MTV QLKTDV Thủy lợi TP | G15: 400 | H15: Sông Đập | I15: Nguyễn Cữu Phú
C16: =C15+1 -> 9 | D16: Nhánh kênh số 5 | E16: Sở Nông nghiệp và Phát triển nông thôn | F16: Công ty TNHH MTV QLKTDV Thủy lợi TP | G16: 400 | H16: Sông Đập | I16: Nguyễn Cữu Phú
C17: =C16+1 -> 10 | D17: Suối Nhum | E17: Sở Nông nghiệp và Phát triển nông thôn | F17: Công ty TNHH MTV QLKTDV Thủy lợi TP | G17: 6260 | H17: Ngã ba sông Xuân Trường | I17: Xa lộ Hà Nội
C18: =C17+1 -> 11 | D18: Suối Cái | E18: Sở Nông nghiệp và Phát triển nông thôn | F18: Công ty TNHH MTV QLKTDV Thủy lợi TP | G18: 3500 | H18: Xa lộ Hà Nội | I18: Cuối tuyến
C19: =C18+1 -> 12 | D19: Kênh Liên Vùng (kênh AH-KC) | E19: Sở Nông nghiệp và Phát triển nông thôn | F19: Công ty TNHH MTV QLKTDV Thủy lợi TP | G19: 700 | H19: Kênh C | I19: Đường Võ Văn Vân (ranh Bình Chánh-Bình Tân)
C20: =C19+1 -> 13 | D20: Kênh tiêu T46 | E20: Sở Nông nghiệp và Phát triển nông thôn | F20: Công ty TNHH MTV QLKTDV Thủy lợi TP | G20: 2070 | H20: Quốc Lộ 22 | I20: Kênh N43
C21: =C20+1 -> 14 | D21: Kênh tiêu TCC 1-2 | E21: Sở Nông nghiệp và Phát triển nông thôn | F21: Công ty TNHH MTV QLKTDV Thủy lợi TP | G21: 8238 | H21: Kênh Đông | I21: Cuối tuyến
... C1203: =C1202+1 -> 1196 | D1203: Rạch Dứa - rạch Rữa | E1203: Sở Nông nghiệp và Phát triển nông thôn | F1203: Công ty TNHH MTV QLKTDV Thủy lợi TP | G1203: 7000 | H1203: Sông Sài Gòn | I1203: Dỏng Dài
A1204: 1 | C1204: =C1203+1 -> 1197 | D1204: Rạch Bà Mễn | E1204: Sở Nông nghiệp và Phát triển nông thôn | F1204: Công ty TNHH MTV QLKTDV Thủy lợi TP | G1204: 1650 | H1204: Sông Rạch Tra | I1204: Cầu Bà Mễn
A1205: 2 | C1205: =C1204+1 -> 1198 | D1205: Rạch Ông Bắc | E1205: Sở Nông nghiệp và Phát triển nông thôn | F1205: Công ty TNHH MTV QLKTDV Thủy lợi TP | G1205: 1254 | H1205: Rạch Đá Hàn | I1205: Cuối tuyến
A1206: 3 | C1206: =C1205+1 -> 1199 | D1206: Rạch Rõng Gan | E1206: Sở Nông nghiệp và Phát triển nông thôn | F1206: Công ty TNHH MTV QLKTDV Thủy lợi TP | G1206: 1205 | H1206: Rạch Đá Hàn | I1206: Cuối tuyến
A1207: 5 | C1207: =C1206+1 -> 1200 | D1207: Rạch Đường Đò | E1207: Sở Nông nghiệp và Phát triển nông thôn | F1207: Công ty TNHH MTV QLKTDV Thủy lợi TP | G1207: 3515 | H1207: Cầu Đổ văn Dậy | I1207: Kênh T6
A1208: 6 | C1208: =C1207+1 -> 1201 | D1208: Rõng Dương Da (Đường Đò) | E1208: Sở Nông nghiệp và Phát triển nông thôn | F1208: Công ty TNHH MTV QLKTDV Thủy lợi TP | G1208: 6000 | H1208: Cầu Xáng | I1208: Ngã tư rạch Rõng Trâu
A1209: 7 | C1209: =C1208+1 -> 1202 | D1209: Rạch Bà Phước | E1209: Sở Nông nghiệp và Phát triển nông thôn | F1209: Công ty TNHH MTV QLKTDV Thủy lợi TP | G1209: 2100 | H1209: Đường đất | I1209: Sông Sài Gòn
C1210: =C1209+1 -> 1203 | D1210: Rạch Bà Hồng 20 | E1210: Sở Nông nghiệp và Phát triển nông thôn | F1210: Công ty TNHH MTV QLKTDV Thủy lợi TP | G1210: 400 | H1210: Rạch Bà Mễn | I1210: Rạch Bà Hồng
C1211: =C1210+1 -> 1204 | D1211: Rạch Bà Hồng | E1211: Sở Nông nghiệp và Phát triển nông thôn | F1211: Công ty TNHH MTV QLKTDV Thủy lợi TP | G1211: 3646 | H1211: sông Sài Gòn | I1211: Rạch Bến Đá
C1212: =C1211+1 -> 1205 | D1212: Rạch Đá Hàn - rạch Dứa | E1212: Sở Nông nghiệp và Phát triển nông thôn | F1212: Công ty TNHH MTV QLKTDV Thủy lợi TP | G1212: 10124 | H1212: Rạch Tra | I1212: Sông Sài Gòn
C1213: =C1212+1 -> 1206 | D1213: Rạch Bà Bếp | E1213: Sở Nông nghiệp và Phát triển nông thôn | F1213: Công ty TNHH MTV QLKTDV Thủy lợi TP | G1213: 3348 | H1213: Sông Sài Gòn | I1213: Ngã tư chòm sấu
C1214: =C1213+1 -> 1207 | D1214: Rạch Cây Xanh | E1214: Sở Nông nghiệp và Phát triển nông thôn | F1214: Công ty TNHH MTV QLKTDV Thủy lợi TP | G1214: 3800 | H1214: Sông Rạch Tra | I1214: Ngã tư chòm sấu
C1215: =C1214+1 -> 1208 | D1215: Rạch Đá Hàn | E1215: Sở Nông nghiệp và Phát triển nông thôn | F1215: Công ty TNHH MTV QLKTDV Thủy lợi TP | G1215: 4500 | H1215: Sông Rạch Tra | I1215: Ngã tư chòm sấu
C1216: =C1215+1 -> 1209 | D1216: Rạch Rỏng Gan | E1216: Sở Nông nghiệp và Phát triển nông thôn | F1216: Công ty TNHH MTV QLKTDV Thủy lợi TP | G1216: 250 | H1216: Sông Đá Hàn | I1216: Đường Võ Văn Bích
C1217: =C1216+1 -> 1210 | D1217: Kênh T1 | E1217: Sở Nông nghiệp và Phát triển nông thôn | F1217: Công ty TNHH MTV QLKTDV Thủy lợi TP | G1217: 695 | H1217: Rạch Đường Xuồng | I1217: Đỗ văn Dậy
C1218: =C1217+1 -> 1211 | D1218: Kênh T2 | E1218: Sở Nông nghiệp và Phát triển nông thôn | F1218: Công ty TNHH MTV QLKTDV Thủy lợi TP | G1218: 700 | H1218: Rạch Đường Xuồng | I1218: Đỗ văn Dậy
C1219: =C1218+1 -> 1212 | D1219: Kênh T3 | E1219: Sở Nông nghiệp và Phát triển nông thôn | F1219: Công ty TNHH MTV QLKTDV Thủy lợi TP | G1219: 799 | H1219: Rạch Đường Xuồng | I1219: Kênh Địa Phận
C1220: =C1219+1 -> 1213 | D1220: Kênh T4 | E1220: Sở Nông nghiệp và Phát triển nông thôn | F1220: Công ty TNHH MTV QLKTDV Thủy lợi TP | G1220: 702 | H1220: Rạch Đường Xuồng | I1220: Kênh Địa Phận
C1221: =C1220+1 -> 1214 | D1221: Kênh T5 | E1221: Sở Nông nghiệp và Phát triển nông thôn | F1221: Công ty TNHH MTV QLKTDV Thủy lợi TP | G1221: 660 | H1221: Rạch Đường Xuồng | I1221: Kênh Địa Phận
... C1233: =C1232+1 -> 1226 | D1233: Rạch Cầu Đen | E1233: Sở Nông nghiệp và Phát triển nông thôn | F1233: Công ty TNHH MTV QLKTDV Thủy lợi TP | G1233: 1800 | H1233: Tỉnh Lộ 15 | I1233: Sông Sài Gòn
A1234: 1 | C1234: =C1233+1 -> 1227 | D1234: Rạch Bến Đò | E1234: Sở Nông nghiệp và Phát triển nông thôn | F1234: Quận 9 | G1234: 1255 | H1234: Nguyễn Xiển | I1234: Sông Đồng Nai
...
